<?xml version="1.0" ?>
<!-- =================================================================================== -->
<!-- |    This document was autogenerated by xacro from robots/fr3/fr3.urdf.xacro      | -->
<!-- |    EDITING THIS FILE BY HAND IS NOT RECOMMENDED                                 | -->
<!-- =================================================================================== -->

<!-- Safety control version: safe joint limits are decreased by 0.2 rad -->

<robot name="fr3">
  <!-- sub-link defining detailed meshes for collision with environment -->
  <link name="fr3_link0">
    <visual>
      <geometry>
        <mesh filename="meshes/franka/visual/link0_from_dae.obj"/>
      </geometry>
    </visual>
    <collision>
      <geometry>
        <mesh filename="meshes/franka/collision/link0.obj"/>
      </geometry>
    </collision>
  </link>

  <link name="fr3_link1">
    <visual>
      <geometry>
        <mesh filename="meshes/franka/visual/link1_from_dae.obj"/>
      </geometry>
    </visual>
    <collision>
      <geometry>
        <mesh filename="meshes/franka/collision/link1.obj"/>
      </geometry>
    </collision>
    <inertial>
      <origin rpy="0 0 0" xyz="0.00033 -0.02204 -0.04762"/>
      <mass value="2.797"/>
      <inertia ixx="0.0156" ixy="0.0" ixz="0.0" iyy="0.01439" iyz="-0.0024" izz="0.005"/>
    </inertial>
  </link>
  <joint name="fr3_joint1" type="revolute">
    <origin rpy="0 0 0" xyz="0 0 0.333"/>
    <parent link="fr3_link0"/>
    <child link="fr3_link1"/>
    <axis xyz="0 0 1"/>
    <limit effort="87.0" lower="-2.54" upper="2.54" velocity="2.0"/>
    <dynamics D="1" K="7000" damping="0.003" friction="0.0" mu_coulomb="0" mu_viscous="16"/>
  </joint>

  <link name="fr3_link2">
    <visual>
      <geometry>
        <mesh filename="meshes/franka/visual/link2_from_dae.obj"/>
      </geometry>
    </visual>
    <collision>
      <geometry>
         <mesh filename="meshes/franka/collision/link2.obj"/>
      </geometry>
    </collision>
    <inertial>
      <origin rpy="0 0 0" xyz="0.00038 -0.09211 0.01908"/>
      <mass value="2.542"/>
      <inertia ixx="0.0166" ixy="0.0" ixz="0.0" iyy="0.0046" iyz="0.0035" izz="0.015"/>
    </inertial>
  </link>
  <joint name="fr3_joint2" type="revolute">
    <origin rpy="-1.5707963267948966 0 0" xyz="0 0 0"/>
    <parent link="fr3_link1"/>
    <child link="fr3_link2"/>
    <axis xyz="0 0 1"/>
    <limit effort="87.0" lower="-1.58" upper="1.58" velocity="1.0"/>
    <dynamics D="1" K="7000" damping="0.003" friction="0.0" mu_coulomb="0" mu_viscous="16"/>
  </joint>

  <link name="fr3_link3">
    <visual>
      <geometry>
        <mesh filename="meshes/franka/visual/link3_from_dae.obj"/>
      </geometry>
    </visual>
    <collision>
      <geometry>
        <mesh filename="meshes/franka/collision/link3.obj"/>
      </geometry>
    </collision>
    <inertial>
      <origin rpy="0 0 0" xyz="0.05152 0.01696 -0.02971"/>
      <mass value="2.2513"/>
      <inertia ixx="0.006" ixy="0.009" ixz="0.003" iyy="0.0086" iyz="0.009" izz="0.0065"/>
    </inertial>
  </link>
  <joint name="fr3_joint3" type="revolute">
    <origin rpy="1.5707963267948966 0 0" xyz="0 -0.316 0"/>
    <parent link="fr3_link2"/>
    <child link="fr3_link3"/>
    <axis xyz="0 0 1"/>
    <limit effort="87.0" lower="-2.69" upper="2.69" velocity="1.5"/>
    <dynamics D="1" K="7000" damping="0.003" friction="0.0" mu_coulomb="0" mu_viscous="16"/>
  </joint>
  
  <link name="fr3_link4">
    <visual>
      <geometry>
        <mesh filename="meshes/franka/visual/link4_from_dae.obj"/>
      </geometry>
    </visual>
    <collision>
      <geometry>
        <mesh filename="meshes/franka/collision/link4.obj"/>
      </geometry>
    </collision>
    <inertial>
      <origin rpy="0 0 0" xyz="-0.05113 0.05825 0.01698"/>
      <mass value="2.2037"/>
      <inertia ixx="0.0156" ixy="0.0" ixz="0.0" iyy="0.01439" iyz="-0.0024" izz="0.005"/>
    </inertial>
  </link>
  <joint name="fr3_joint4" type="revolute">
    <origin rpy="1.5707963267948966 0 0" xyz="0.0825 0 0"/>
    <parent link="fr3_link3"/>
    <child link="fr3_link4"/>
    <axis xyz="0 0 1"/>
    <limit effort="87.0" lower="-2.84" upper="-0.35" velocity="1.25"/>
    <dynamics D="1" K="7000" damping="0.003" friction="0.0" mu_coulomb="0" mu_viscous="16"/>
  </joint>

  <link name="fr3_link5">
    <visual>
      <geometry>
        <mesh filename="meshes/franka/visual/link5_from_dae.obj"/>
      </geometry>
    </visual>
    <collision>
      <geometry>
        <mesh filename="meshes/franka/collision/link5.obj"/>
      </geometry>
    </collision>
    <inertial>
      <origin rpy="0 0 0" xyz="-0.00005 0.03730 -0.09280"/>
      <mass value="2.2855"/>
      <inertia ixx="0.02297014781" ixy="0.0" ixz="0.0" iyy="0.02095060919" iyz="0.00382345782" izz="0.00430606551"/>
    </inertial>
  </link>
  <joint name="fr3_joint5" type="revolute">
    <origin rpy="-1.5707963267948966 0 0" xyz="-0.0825 0.384 0"/>
    <parent link="fr3_link4"/>
    <child link="fr3_link5"/>
    <axis xyz="0 0 1"/>
    <limit effort="12.0" lower="-2.60" upper="2.60" velocity="3.0"/>
    <dynamics D="1" K="7000" damping="0.003" friction="0.0" mu_coulomb="0" mu_viscous="16"/>
  </joint>

  <link name="fr3_link6">
    <visual>
      <geometry>
        <mesh filename="meshes/franka/visual/link6_from_dae.obj"/>
      </geometry>
    </visual>
    <collision>
      <geometry>
        <mesh filename="meshes/franka/collision/link6.obj"/>
      </geometry>
    </collision>
    <inertial>
      <origin rpy="0 0 0" xyz="0.06572 -0.00371 0.00153"/>
      <mass value="1.353"/>
      <inertia ixx="0.00087964522" ixy="-0.00021487814" ixz="-0.00011911662" iyy="0.00277796968" iyz="0.00001274322" izz="0.00286701969"/>
    </inertial>
  </link>
  <joint name="fr3_joint6" type="revolute">
    <origin rpy="1.5707963267948966 0 0" xyz="0 0 0"/>
    <parent link="fr3_link5"/>
    <child link="fr3_link6"/>
    <axis xyz="0 0 1"/>
    <limit effort="12.0" lower="0.75" upper="4.31" velocity="1.5"/>
    <dynamics D="1" K="7000" damping="0.003" friction="0.0" mu_coulomb="0" mu_viscous="16"/>
  </joint>
  
  <link name="fr3_link7">
    <visual>
      <geometry>
        <mesh filename="meshes/franka/visual/link7_from_dae.obj"/>
      </geometry>
    </visual>
    <collision>
      <geometry>
        <mesh filename="meshes/franka/collision/link7.obj"/>
      </geometry>
    </collision>
    <inertial>
      <origin rpy="0 0 0" xyz="0.00089 -0.00044 0.05491"/>
      <mass value="0.35973"/>
      <inertia ixx="0.00019541063" ixy="0.00000165231" ixz="0.00000148826" iyy="0.00019210361" iyz="-0.00000131132" izz="0.00017936256"/>
    </inertial>
  </link>
  <joint name="fr3_joint7" type="revolute">
    <origin rpy="1.5707963267948966 0 0" xyz="0.088 0 0"/>
    <parent link="fr3_link6"/>
    <child link="fr3_link7"/>
    <axis xyz="0 0 1"/>
    <limit effort="12.0" lower="-2.81" upper="2.81" velocity="3.0"/>
    <dynamics D="1" K="7000" damping="0.003" friction="0.0" mu_coulomb="0" mu_viscous="16"/>
  </joint>
  
  <link name="fr3_link8"/>
  <joint name="fr3_joint8" type="fixed">
    <origin rpy="0 0 0" xyz="0 0 0.107"/>
    <parent link="fr3_link7"/>
    <child link="fr3_link8"/>
  </joint>

  <link name="L_flange">
    <inertial>
      <origin xyz="0 0 0" rpy="0 0 0"/>
      <mass value="0.1"/>
      <inertia ixx="0.0001" ixy="0" ixz="0" iyy="0.0001" iyz="0" izz="0.0001"/>
    </inertial>
    <visual>
      <origin xyz="4.71628e-18 -3.46945e-18 -0.009" rpy="3.14159 -0 0"/>
      <geometry>
        <mesh filename="./meshes/L_flange_stable.stl"/>
      </geometry>
      <material name="flange_material">
        <color rgba="0.0 0.0 0.0 1.0"/>
      </material>
    </visual>
    <collision>
      <origin xyz="4.71628e-18 -3.46945e-18 -0.009" rpy="3.14159 -0 0"/>
      <geometry>
        <mesh filename="./meshes/L_flange_stable.stl"/>
      </geometry>
    </collision>
  </link>

  <joint name="franka2flange" type="fixed">
    <origin xyz="0 0 0" rpy="3.14159 -0 1.5708"/>
    <parent link="fr3_link8"/>
    <child link="L_flange"/>
  </joint>

  <joint name="flange2wrist" type="fixed">
    <origin xyz="0 0.0415 -0.068767" rpy="1.5708 -0 3.14159"/>
    <parent link="L_flange"/>
    <child link="wrist"/>
  </joint>

<!--BeginRightADD-->
  <link name="wrist"/>
    <joint name="R_hand_base_joint" type="fixed">
      <origin
      xyz="0 0 0"
      rpy="3.14 0 0" />
      <parent link="wrist"/>
      <child link="base_link"/>
    </joint>
  
  <link
    name="base_link">
    <inertial>
      <origin
        xyz="-4.91696692515552E-05 -0.00297934158474353 -0.0724838074966582"
        rpy="0 0 0" />
      <mass
        value="0.260034351097693" />
      <inertia
        ixx="0.000240584294557413"
        ixy="1.12900341553271E-06"
        ixz="5.34716263010627E-07"
        iyy="0.000284423438713157"
        iyz="-1.41174524262487E-05"
        izz="0.000155854672271766" />
    </inertial>
    <visual>
      <origin
        xyz="0 0 0"
        rpy="0 0 0" />
      <geometry>
        <mesh
          filename="./meshes/inspire_color/right_base_link.obj" />
      </geometry>
      <!-- <material
        name="">
        <color
          rgba="1 1 1 1" />
      </material> -->
    </visual>
    <collision>
      <origin
        xyz="0 0 0"
        rpy="0 0 0" />
      <geometry>
        <mesh
          filename="./meshes/right_base_link.STL" />
      </geometry>
    </collision>
  </link>
  <link
    name="right_thumb_1">
    <inertial>
      <origin
        xyz="-0.00178423179132732 0.000649410769092404 0.00488589310434417"
        rpy="0 0 0" />
      <mass
        value="0.00115518743162309" />
      <inertia
        ixx="5.98911473694571E-08"
        ixy="-8.04324266712912E-09"
        ixz="-3.29346964287939E-09"
        iyy="4.07201940087006E-08"
        iyz="1.1987242259973E-09"
        izz="6.18161684388651E-08" />
    </inertial>
    <visual>
      <origin
        xyz="0 0 0"
        rpy="0 0 0" />
      <geometry>
        <mesh
          filename="./meshes/calibrated/right_thumb_1.STL" />
      </geometry>
      <material
        name="">
        <color
          rgba="1 1 1 1" />
      </material>
    </visual>
    <collision>
      <origin
        xyz="0 0 0"
        rpy="0 0 0" />
      <geometry>
        <mesh
          filename="./meshes/calibrated/right_thumb_1.STL" />
      </geometry>
    </collision>
  </link>
  <joint
    name="right_thumb_1_joint"
    type="revolute">
    <origin
      xyz="0.0269 0.02101 -0.069"
      rpy="-3.1416 0 -3.1416" />
    <parent
      link="base_link" />
    <child
      link="right_thumb_1" />
    <axis
      xyz="0 0 -1" />
    <limit
      lower="0"
      upper="1.15"
      effort="1"
      velocity="100" />
  </joint>
  <link
    name="right_thumb_2">
    <inertial>
      <origin
        xyz="0.0141071308121962 0.0132720367246953 -0.00905029680056009"
        rpy="0 0 0" />
      <mass
        value="0.016" />
      <inertia
        ixx="1.06573287501608E-06"
        ixy="-7.61985755293293E-08"
        ixz="-2.57609628655293E-11"
        iyy="1.06536320559038E-06"
        iyz="5.09603163270097E-12"
        izz="1.39688473195303E-06" />
    </inertial>
    <visual>
      <origin
        xyz="0 0 0"
        rpy="0 0 0" />
      <geometry>
        <mesh
          filename="./meshes/calibrated/inspire_color/right_thumb_2.obj" />
      </geometry>
      <!-- <material
        name="">
        <color
          rgba="1 1 1 1" />
      </material> -->
    </visual>
    <collision>
      <origin
        xyz="0 0 0"
        rpy="0 0 0" />
      <geometry>
        <mesh
          filename="./meshes/calibrated/right_thumb_2.STL" />
      </geometry>
    </collision>
  </link>
  <joint
    name="right_thumb_2_joint"
    type="revolute">
    <origin
      xyz="-0.0063016 0.011924 0.003"
      rpy="1.5708 0 2.7925" />
    <parent
      link="right_thumb_1" />
    <child
      link="right_thumb_2" />
    <axis
      xyz="0 0 1" />
    <limit
      lower="0"
      upper="0.35"
      effort="1"
      velocity="100" />
  </joint>
  <link
    name="right_thumb_3">
    <inertial>
      <origin
        xyz="0.00937843602210774 0.00404407714692963 -0.00753947150343212"
        rpy="0 0 0" />
      <mass
        value="0.012" />
      <inertia
        ixx="4.67837152048068E-07"
        ixy="-4.50034504480504E-08"
        ixz="-7.50604972036399E-11"
        iyy="3.98821847444202E-07"
        iyz="-2.80308780973008E-10"
        izz="4.24792779381109E-07" />
    </inertial>
    <visual>
      <origin
        xyz="0 0 0"
        rpy="0 0 0" />
      <geometry>
        <mesh
          filename="./meshes/calibrated/inspire_color/right_thumb_3.obj" />
      </geometry>
      <!-- <material
        name="">
        <color
          rgba="1 1 1 1" />
      </material> -->
    </visual>
    <collision>
      <origin
        xyz="0 0 0"
        rpy="0 0 0" />
      <geometry>
        <mesh
          filename="./meshes/calibrated/right_thumb_3.STL" />
      </geometry>
    </collision>
  </link>
  <joint
    name="right_thumb_3_joint"
    type="revolute">
    <origin
      xyz="0.034968 0.021325 -0.0015"
      rpy="0 0 0" />
    <parent
      link="right_thumb_2" />
    <child
      link="right_thumb_3" />
    <axis
      xyz="0 0 1" />
    <limit
      lower="0"
      upper="0.21"
      effort="1"
      velocity="100" />
    <mimic
        joint="right_thumb_2_joint"
        multiplier="0.60"
        offset="0" />
  </joint>
  <link
    name="right_thumb_4">
    <inertial>
      <origin
        xyz="0.0109973997213043 0.00131062737520288 -0.0073435196000655"
        rpy="0 0 0" />
      <mass
        value="0.01" />
      <inertia
        ixx="6.43617695804108E-07"
        ixy="-2.57371067432159E-07"
        ixz="8.83834214745077E-10"
        iyy="7.63665185138253E-07"
        iyz="7.47494238463672E-10"
        izz="9.2568863295396E-07" />
    </inertial>
    <visual>
      <origin
        xyz="0 0 0"
        rpy="0 0 0" />
      <geometry>
        <mesh
          filename="./meshes/calibrated/inspire_color/right_thumb_4.obj" />
      </geometry>
      <!-- <material
        name="">
        <color
          rgba="1 1 1 1" />
      </material> -->
    </visual>
    <collision>
      <origin
        xyz="0 0 0"
        rpy="0 0 0" />
      <geometry>
        <mesh
          filename="./meshes/calibrated/right_thumb_4.STL" />
      </geometry>
    </collision>
  </link>
  <joint
    name="right_thumb_4_joint"
    type="revolute">
    <origin
      xyz="0.018887 0.011501 -0.0002"
      rpy="0 0 0" />
    <parent
      link="right_thumb_3" />
    <child
      link="right_thumb_4" />
    <axis
      xyz="0 0 1" />
    <limit
      lower="0"
      upper="0.28"
      effort="1"
      velocity="100" />
    <mimic
        joint="right_thumb_2_joint"
        multiplier="0.8"
        offset="0" />
  </joint>
  <link
    name="right_index_1">
    <inertial>
      <origin
        xyz="-0.00183546255523356 0.0123552521861834 -0.00664922294778368"
        rpy="0 0 0" />
      <mass
        value="0.00719999389753264" />
      <inertia
        ixx="1.28371991025318E-06"
        ixy="4.21564829206078E-08"
        ixz="-4.10859703056649E-12"
        iyy="5.79478432222904E-07"
        iyz="6.39690407239206E-11"
        izz="1.32925246769088E-06" />
    </inertial>
    <visual>
      <origin
        xyz="0 0 0"
        rpy="0 0 0" />
      <geometry>
        <mesh
          filename="./meshes/inspire_color/right_index_1.obj" />
      </geometry>
      <!-- <material
        name="">
        <color
          rgba="1 1 1 1" />
      </material> -->
    </visual>
    <collision>
      <origin
        xyz="0 0 0"
        rpy="0 0 0" />
      <geometry>
        <mesh
          filename="./meshes/right_index_1.STL" />
      </geometry>
    </collision>
  </link>
  <joint
    name="right_index_1_joint"
    type="revolute">
    <origin
      xyz="0.038679 0.00056467 -0.1564"
      rpy="-1.5359 0 -1.5708" />
    <parent
      link="base_link" />
    <child
      link="right_index_1" />
    <axis
      xyz="0 0 1" />
    <limit
      lower="0"
      upper="0.9"
      effort="1"
      velocity="100" />
  </joint>
  <link
    name="right_index_2">
    <inertial>
      <origin
        xyz="0.000405081354201142 0.0257028143581744 -0.00609275623125877"
        rpy="0 0 0" />
      <mass
        value="0.0096859422185797" />
      <inertia
        ixx="2.25513837942244E-06"
        ixy="4.11239564383381E-07"
        ixz="-3.94499739658711E-10"
        iyy="3.91290903748666E-07"
        iyz="2.79706871963245E-09"
        izz="2.30200483771215E-06" />
    </inertial>
    <visual>
      <origin
        xyz="0 0 0"
        rpy="0 0 0" />
      <geometry>
        <mesh
          filename="./meshes/inspire_color/right_index_2.obj" />
      </geometry>
      <!-- <material
        name="">
        <color
          rgba="1 1 1 1" />
      </material> -->
    </visual>
    <collision>
      <origin
        xyz="0 0 0"
        rpy="0 0 0" />
      <geometry>
        <mesh
          filename="./meshes/right_index_2.STL" />
      </geometry>
    </collision>
  </link>
  <joint
    name="right_index_2_joint"
    type="revolute">
    <origin
      xyz="-0.0016312 0.032734 -0.00055"
      rpy="0 0 0" />
    <parent
      link="right_index_1" />
    <child
      link="right_index_2" />
    <axis
      xyz="0 0 1" />
    <limit
      lower="0"
      upper="0.945"
      effort="1"
      velocity="100" />
    <mimic
        joint="right_index_1_joint"
        multiplier="1.05"
        offset="0" />
  </joint>
  <link
    name="right_middle_1">
    <inertial>
      <origin
        xyz="-0.00229221489529491 0.0122787164691098 -0.00664923691414206"
        rpy="0 0 0" />
      <mass
        value="0.00719999454699651" />
      <inertia
        ixx="1.27961146095209E-06"
        ixy="6.81307502326408E-08"
        ixz="-6.13869092479439E-12"
        iyy="5.83570383259162E-07"
        iyz="6.33401074034573E-11"
        izz="1.32923656099557E-06" />
    </inertial>
    <visual>
      <origin
        xyz="0 0 0"
        rpy="0 0 0" />
      <geometry>
        <mesh
          filename="./meshes/inspire_color/right_middle_1.obj" />
      </geometry>
      <!-- <material
        name="">
        <color
          rgba="1 1 1 1" />
      </material> -->
    </visual>
    <collision>
      <origin
        xyz="0 0 0"
        rpy="0 0 0" />
      <geometry>
        <mesh
          filename="./meshes/right_middle_1.STL" />
      </geometry>
    </collision>
  </link>
  <joint
    name="right_middle_1_joint"
    type="revolute">
    <origin
      xyz="0.0171 0.00056467 -0.157"
      rpy="-1.5708 0 -1.5708" />
    <parent
      link="base_link" />
    <child
      link="right_middle_1" />
    <axis
      xyz="0 0 1" />
    <limit
      lower="0"
      upper="0.95"
      effort="1"
      velocity="100" />
  </joint>
  <link
    name="right_middle_2">
    <inertial>
      <origin
        xyz="7.55635061812504E-05 0.0274472409700489 -0.00610051225570537"
        rpy="0 0 0" />
      <mass
        value="0.0104603374357648" />
      <inertia
        ixx="2.75802690517233E-06"
        ixy="4.66354191789105E-07"
        ixz="-3.73412436067728E-12"
        iyy="4.22418749660047E-07"
        iyz="7.48571284682703E-11"
        izz="2.80694637912416E-06" />
    </inertial>
    <visual>
      <origin
        xyz="0 0 0"
        rpy="0 0 0" />
      <geometry>
        <mesh
          filename="./meshes/inspire_color/right_middle_2.obj" />
      </geometry>
      <!-- <material
        name="">
        <color
          rgba="1 1 1 1" />
      </material> -->
    </visual>
    <collision>
      <origin
        xyz="0 0 0"
        rpy="0 0 0" />
      <geometry>
        <mesh
          filename="./meshes/right_middle_2.STL" />
      </geometry>
    </collision>
  </link>
  <joint
    name="right_middle_2_joint"
    type="revolute">
    <origin
      xyz="-0.0028436 0.032651 -0.00055"
      rpy="0 0 0" />
    <parent
      link="right_middle_1" />
    <child
      link="right_middle_2" />
    <axis
      xyz="0 0 1" />
    <limit
      lower="0"
      upper="0.9975"
      effort="1"
      velocity="100" />
    <mimic
        joint="right_middle_1_joint"
        multiplier="1.05"
        offset="0" />
  </joint>
  <link
    name="right_ring_1">
    <inertial>
      <origin
        xyz="-0.00240481178777661 0.0122571709475593 -0.00664923625225445"
        rpy="0 0 0" />
      <mass
        value="0.00719998997814135" />
      <inertia
        ixx="1.27830103769765E-06"
        ixy="7.45073064952646E-08"
        ixz="-6.73880804360017E-12"
        iyy="5.84879553082369E-07"
        iyz="6.3350585052199E-11"
        izz="1.32923557625193E-06" />
    </inertial>
    <visual>
      <origin
        xyz="0 0 0"
        rpy="0 0 0" />
      <geometry>
        <mesh
          filename="./meshes/inspire_color/right_ring_1.obj" />
      </geometry>
      <!-- <material
        name="">
        <color
          rgba="1 1 1 1" />
      </material> -->
    </visual>
    <collision>
      <origin
        xyz="0 0 0"
        rpy="0 0 0" />
      <geometry>
        <mesh
          filename="./meshes/right_ring_1.STL" />
      </geometry>
    </collision>
  </link>
  <joint
    name="right_ring_1_joint"
    type="revolute">
    <origin
      xyz="-0.0045302 0.00056467 -0.15683"
      rpy="-1.6232 0 -1.5708" />
    <parent
      link="base_link" />
    <child
      link="right_ring_1" />
    <axis
      xyz="0 0 1" />
    <limit
      lower="0"
      upper="1.15"
      effort="1"
      velocity="100" />
  </joint>
  <link
    name="right_ring_2">
    <inertial>
      <origin
        xyz="0.000666830906754845 0.0256973412492289 -0.0060927714564012"
        rpy="0 0 0" />
      <mass
        value="0.0096859390369724" />
      <inertia
        ixx="2.26332196405867E-06"
        ixy="3.92172318180451E-07"
        ixz="-3.65715440420713E-10"
        iyy="3.83108005467821E-07"
        iyz="2.80158649618184E-09"
        izz="2.30200501593561E-06" />
    </inertial>
    <visual>
      <origin
        xyz="0 0 0"
        rpy="0 0 0" />
      <geometry>
        <mesh
          filename="./meshes/inspire_color/right_ring_2.obj" />
      </geometry>
      <!-- <material
        name="">
        <color
          rgba="1 1 1 1" />
      </material> -->
    </visual>
    <collision>
      <origin
        xyz="0 0 0"
        rpy="0 0 0" />
      <geometry>
        <mesh
          filename="./meshes/right_ring_2.STL" />
      </geometry>
    </collision>
  </link>
  <joint
    name="right_ring_2_joint"
    type="revolute">
    <origin
      xyz="-0.0031431 0.032624 -0.00055"
      rpy="0 0 0" />
    <parent
      link="right_ring_1" />
    <child
      link="right_ring_2" />
    <axis
      xyz="0 0 1" />
    <limit
      lower="0"
      upper="1.2075"
      effort="1"
      velocity="100" />
    <mimic
        joint="right_ring_1_joint"
        multiplier="1.05"
        offset="0" />
  </joint>
  <link
    name="right_little_1">
    <inertial>
      <origin
        xyz="-0.00316844591541324 0.0120823779446085 -0.00664923024026526"
        rpy="0 0 0" />
      <mass
        value="0.00719994987013217" />
      <inertia
        ixx="1.26624415714453E-06"
        ixy="1.17303714016617E-07"
        ixz="-1.15327375313821E-11"
        iyy="5.96925804604496E-07"
        iyz="6.36110319315301E-11"
        izz="1.32922857962206E-06" />
    </inertial>
    <visual>
      <origin
        xyz="0 0 0"
        rpy="0 0 0" />
      <geometry>
        <mesh
          filename="./meshes/inspire_color/right_little_1.obj" />
      </geometry>
      <!-- <material
        name="">
        <color
          rgba="1 1 1 1" />
      </material> -->
    </visual>
    <collision>
      <origin
        xyz="0 0 0"
        rpy="0 0 0" />
      <geometry>
        <mesh
          filename="./meshes/right_little_1.STL" />
      </geometry>
    </collision>
  </link>
  <joint
    name="right_little_1_joint"
    type="revolute">
    <origin
      xyz="-0.025916 0.00056467 -0.15365"
      rpy="-1.6755 -0.06 -1.5708" />
    <parent
      link="base_link" />
    <child
      link="right_little_1" />
    <axis
      xyz="0 0 1" />
    <limit
      lower="0"
      upper="1.3"
      effort="1"
      velocity="100" />
  </joint>
  <link
    name="right_little_2">
    <inertial>
      <origin
        xyz="0.0204417303421136 -0.00469494170410353 -0.00609999668427265"
        rpy="0 0 0" />
      <mass
        value="0.0075928240732547" />
      <inertia
        ixx="2.31546812157118E-07"
        ixy="-7.27021381773956E-08"
        ixz="2.3664966486269E-11"
        iyy="1.27663957628266E-06"
        iyz="-7.58283070676144E-12"
        izz="1.23909562166535E-06" />
    </inertial>
    <visual>
      <origin
        xyz="0 0 0"
        rpy="0 0 0" />
      <geometry>
        <mesh
          filename="./meshes/inspire_color/right_little_2.obj" />
      </geometry>
      <!-- <material
        name="">
        <color
          rgba="1 1 1 1" />
      </material> -->
    </visual>
    <collision>
      <origin
        xyz="0 0 0"
        rpy="0 0 0" />
      <geometry>
        <mesh
          filename="./meshes/right_little_2.STL" />
      </geometry>
    </collision>
  </link>
  <joint
    name="right_little_2_joint"
    type="revolute">
    <origin
      xyz="-0.005182 0.032363 -0.00055"
      rpy="0 0 1.7808" />
    <parent
      link="right_little_1" />
    <child
      link="right_little_2" />
    <axis
      xyz="0 0 1" />
    <limit
      lower="0"
      upper="1.365"
      effort="1"
      velocity="100" />
    <mimic
        joint="right_little_1_joint"
        multiplier="1.05"
        offset="0" />  
  </joint>


  <!-- define fingertips-->
  <link name="right_thumb_tip"/>
  <joint name="right_thumb_tip_joint" type="fixed">
    <origin rpy="0 0 0" xyz="0.025 0.02 -0.007"/>
    <parent link="right_thumb_4"/>
    <child link="right_thumb_tip"/>
  </joint>

  <link name="right_index_tip"/>
  <joint name="right_index_tip_joint" type="fixed">
    <origin rpy="0 0 0" xyz="-0.007 0.053 -0.006"/>
    <parent link="right_index_2"/>
    <child link="right_index_tip"/>
  </joint>

  <link name="right_middle_tip"/>
  <joint name="right_middle_tip_joint" type="fixed">
    <origin rpy="0 0 0" xyz="-0.007 0.057 -0.006"/>
    <parent link="right_middle_2"/>
    <child link="right_middle_tip"/>
  </joint>

  <link name="right_ring_tip"/>
  <joint name="right_ring_tip_joint" type="fixed">
    <origin rpy="0 0 0" xyz="-0.007 0.053 -0.006"/>
    <parent link="right_ring_2"/>
    <child link="right_ring_tip"/>
  </joint>

  <link name="right_little_tip"/>
  <joint name="right_little_tip_joint" type="fixed">
    <origin rpy="0 0 -1.5708" xyz="0.043 -0.001 -0.006"/>
    <parent link="right_little_2"/>
    <child link="right_little_tip"/>
  </joint>
</robot>

